Workbook

Sheet ซื้อสินค้า
A1: วันที่ | B1: ชื่อสินค้า | C1: ราคา | D1: หน่วยนับ | E1: จำนวนที่ซื้อ | F1: ต้นทุนอื่นๆ | G1: มูลค่ารวม | H1: เลข Lot | I1: จำนวนสินค้าคงเหลือ | J1: ต้นทุนเฉลี่ยสินค้าต่อชิ้น | K1: ยอดขายเฉลี่ยต่อชิ้น | L1: อัตรากำไร % เฉลี่ยต่อชิ้นต่อ lot | M1: มูลค่าสินค้าคงเหลือ
A2: 45660 | B2: Yamaha P-45 Digital Piano | C2: 18500 | D2: ตัว | E2: 3 | F2: 500 | G2: 56000 | H2: 1 | I2: 5 | J2: 17500 | K2: 18500 | L2: 0.0571 | M2: 87500
A3: 45660 | B3: Kala KA-15S Ukulele | C3: 3800 | D3: ตัว | E3: 5 | F3: 0 | G3: 19000 | H3: 1 | I3: 10 | J3: 3800 | K3: 0 | L3: 0 | M3: 38000
A4: 45667 | B4: Fender Player Stratocaster Electric Guitar | C4: 24900 | D4: ตัว | E4: 2 | F4: 0 | G4: 49800 | H4: 2 | I4: 3 | J4: 24900 | K4: 26250 | L4: 0.05 | M4: 74700
A5: 45684 | B5: Pearl Export Drum Set EXX725SP | C5: 38000 | D5: ชุด | E5: 2 | F5: 0 | G5: 76000 | H5: 1 | I5: 1 | J5: 38000 | K5: 0 | L5: 0 | M5: 38000
A6: 45684 | B6: Roland GO:KEYS 61 Digital Keyboard | C6: 14900 | D6: ตัว | E6: 10 | F6: 0 | G6: 149000 | H6: 1 | I6: 7 | J6: 14900 | K6: 15500 | L6: 0.0323 | M6: 103300
A7: 45685 | B7: Suzuki M-37C Melodica | C7: 3200 | D7: ตัว | E7: 5 | F7: 0 | G7: 16000 | H7: 3 | I7: 15 | J7: 3200 | K7: 0 | L7: 0 | M7: 48000
A8: 45687 | B8: Yamaha YFL-222 Flute | C8: 26000 | D8: ตัว | E8: 2 | F8: 500 | G8: 53000 | H8: 1 | I8: 5 | J8: 25500 | K8: 26000 | L8: 0.0196 | M8: 127500
A9: 45688 | B9: Ibanez GSR200 Bass Guitar | C9: 12500 | D9: ตัว | E9: 3 | F9: 0 | G9: 37500 | H9: 1 | I9: 8 | J9: 12500 | K9: 13125 | L9: 0.05 | M9: 100000
A10: 45689 | B10: Hohner Special 20 Harmonica | C10: 1800 | D10: ตัว | E10: 6 | F10: 0 | G10: 10800 | H10: 1 | I10: 20 | J10: 1800 | K10: 0 | L10: 0 | M10: 36000
A11: 45690 | B11: Korg B2 Digital Piano | C11: 22000 | D11: ตัว | E11: 2 | F11: 0 | G11: 44000 | H11: 1 | I11: 3 | J11: 22000 | K11: 23000 | L11: 0.0455 | M11: 66000
A12: 45691 | B12: Yamaha C40 Classical Guitar | C12: 4500 | D12: ตัว | E12: 4 | F12: 0 | G12: 18000 | H12: 1 | I12: 10 | J12: 4500 | K12: 0 | L12: 0 | M12: 45000
A13: 45692 | B13: Fender Squier Bullet Stratocaster | C13: 8500 | D13: ตัว | E13: 3 | F13: 0 | G13: 25500 | H13: 1 | I13: 5 | J13: 8500 | K13: 0 | L13: 0 | M13: 42500
... A54: 45733 | B54: Yamaha YTR-2330 Trumpet | C54: 12500 | D54: ตัว | E54: 1 | F54: 0 | G54: 12500 | H54: 1 | I54: 2 | J54: 12500 | K54: 0 | L54: 0 | M54: 25000
C55: =IFERROR(VLOOKUP(B55,ชื่อสินค้า!A:C,2,FALSE),) -> 0 | D55: =IFERROR(VLOOKUP(B55,ชื่อสินค้า!A:D,4,FALSE),"") | G55: =IF(LEN(B55)>0,C55*E55+F55,"") | H55: =IF(B55<>"",COUNTIF($B$2:B55, B55) & "-" & B55,) -> 0 | I55: =IF(G55<>"",E55-SUMIFS(ขายสินค้า!E:E,ขายสินค้า!G:G,H55),) -> 0 | J55: =IF(G55<>"",G55/E55,) -> 0 | K55: =IF(B55<>"", IFERROR(SUMIF(ขายสินค้า!G:G,H55,ขายสินค้า!F:F)/(E55-I55),0),) -> 0 | L55: =IF(B55<>"",IFERROR((K55-J55)/K55,0),) -> 0 | M55: =IF(G55<>"",I55*J55,) -> 0
C56: =IFERROR(VLOOKUP(B56,ชื่อสินค้า!A:C,2,FALSE),) -> 0 | D56: =IFERROR(VLOOKUP(B56,ชื่อสินค้า!A:D,4,FALSE),"") | G56: =IF(LEN(B56)>0,C56*E56+F56,"") | H56: =IF(B56<>"",COUNTIF($B$2:B56, B56) & "-" & B56,) -> 0 | I56: =IF(G56<>"",E56-SUMIFS(ขายสินค้า!E:E,ขายสินค้า!G:G,H56),) -> 0 | J56: =IF(G56<>"",G56/E56,) -> 0 | K56: =IF(B56<>"", IFERROR(SUMIF(ขายสินค้า!G:G,H56,ขายสินค้า!F:F)/(E56-I56),0),) -> 0 | L56: =IF(B56<>"",IFERROR((K56-J56)/K56,0),) -> 0 | M56: =IF(G56<>"",I56*J56,) -> 0
C57: =IFERROR(VLOOKUP(B57,ชื่อสินค้า!A:C,2,FALSE),) -> 0 | D57: =IFERROR(VLOOKUP(B57,ชื่อสินค้า!A:D,4,FALSE),"") | G57: =IF(LEN(B57)>0,C57*E57+F57,"") | H57: =IF(B57<>"",COUNTIF($B$2:B57, B57) & "-" & B57,) -> 0 | I57: =IF(G57<>"",E57-SUMIFS(ขายสินค้า!E:E,ขายสินค้า!G:G,H57),) -> 0 | J57: =IF(G57<>"",G57/E57,) -> 0 | K57: =IF(B57<>"", IFERROR(SUMIF(ขายสินค้า!G:G,H57,ขายสินค้า!F:F)/(E57-I57),0),) -> 0 | L57: =IF(B57<>"",IFERROR((K57-J57)/K57,0),) -> 0 | M57: =IF(G57<>"",I57*J57,) -> 0
C58: =IFERROR(VLOOKUP(B58,ชื่อสินค้า!A:C,2,FALSE),) -> 0 | D58: =IFERROR(VLOOKUP(B58,ชื่อสินค้า!A:D,4,FALSE),"") | G58: =IF(LEN(B58)>0,C58*E58+F58,"") | H58: =IF(B58<>"",COUNTIF($B$2:B58, B58) & "-" & B58,) -> 0 | I58: =IF(G58<>"",E58-SUMIFS(ขายสินค้า!E:E,ขายสินค้า!G:G,H58),) -> 0 | J58: =IF(G58<>"",G58/E58,) -> 0 | K58: =IF(B58<>"", IFERROR(SUMIF(ขายสินค้า!G:G,H58,ขายสินค้า!F:F)/(E58-I58),0),) -> 0 | L58: =IF(B58<>"",IFERROR((K58-J58)/K58,0),) -> 0 | M58: =IF(G58<>"",I58*J58,) -> 0
C59: =IFERROR(VLOOKUP(B59,ชื่อสินค้า!A:C,2,FALSE),) -> 0 | D59: =IFERROR(VLOOKUP(B59,ชื่อสินค้า!A:D,4,FALSE),"") | G59: =IF(LEN(B59)>0,C59*E59+F59,"") | H59: =IF(B59<>"",COUNTIF($B$2:B59, B59) & "-" & B59,) -> 0 | I59: =IF(G59<>"",E59-SUMIFS(ขายสินค้า!E:E,ขายสินค้า!G:G,H59),) -> 0 | J59: =IF(G59<>"",G59/E59,) -> 0 | K59: =IF(B59<>"", IFERROR(SUMIF(ขายสินค้า!G:G,H59,ขายสินค้า!F:F)/(E59-I59),0),) -> 0 | L59: =IF(B59<>"",IFERROR((K59-J59)/K59,0),) -> 0 | M59: =IF(G59<>"",I59*J59,) -> 0
C60: =IFERROR(VLOOKUP(B60,ชื่อสินค้า!A:C,2,FALSE),) -> 0 | D60: =IFERROR(VLOOKUP(B60,ชื่อสินค้า!A:D,4,FALSE),"") | G60: =IF(LEN(B60)>0,C60*E60+F60,"") | H60: =IF(B60<>"",COUNTIF($B$2:B60, B60) & "-" & B60,) -> 0 | I60: =IF(G60<>"",E60-SUMIFS(ขายสินค้า!E:E,ขายสินค้า!G:G,H60),) -> 0 | J60: =IF(G60<>"",G60/E60,) -> 0 | K60: =IF(B60<>"", IFERROR(SUMIF(ขายสินค้า!G:G,H60,ขายสินค้า!F:F)/(E60-I60),0),) -> 0 | L60: =IF(B60<>"",IFERROR((K60-J60)/K60,0),) -> 0 | M60: =IF(G60<>"",I60*J60,) -> 0
C61: =IFERROR(VLOOKUP(B61,ชื่อสินค้า!A:C,2,FALSE),) -> 0 | D61: =IFERROR(VLOOKUP(B61,ชื่อสินค้า!A:D,4,FALSE),"") | G61: =IF(LEN(B61)>0,C61*E61+F61,"") | H61: =IF(B61<>"",COUNTIF($B$2:B61, B61) & "-" & B61,) -> 0 | I61: =IF(G61<>"",E61-SUMIFS(ขายสินค้า!E:E,ขายสินค้า!G:G,H61),) -> 0 | J61: =IF(G61<>"",G61/E61,) -> 0 | K61: =IF(B61<>"", IFERROR(SUMIF(ขายสินค้า!G:G,H61,ขายสินค้า!F:F)/(E61-I61),0),) -> 0 | L61: =IF(B61<>"",IFERROR((K61-J61)/K61,0),) -> 0 | M61: =IF(G61<>"",I61*J61,) -> 0
C62: =IFERROR(VLOOKUP(B62,ชื่อสินค้า!A:C,2,FALSE),) -> 0 | D62: =IFERROR(VLOOKUP(B62,ชื่อสินค้า!A:D,4,FALSE),"") | G62: =IF(LEN(B62)>0,C62*E62+F62,"") | H62: =IF(B62<>"",COUNTIF($B$2:B62, B62) & "-" & B62,) -> 0 | I62: =IF(G62<>"",E62-SUMIFS(ขายสินค้า!E:E,ขายสินค้า!G:G,H62),) -> 0 | J62: =IF(G62<>"",G62/E62,) -> 0 | K62: =IF(B62<>"", IFERROR(SUMIF(ขายสินค้า!G:G,H62,ขายสินค้า!F:F)/(E62-I62),0),) -> 0 | L62: =IF(B62<>"",IFERROR((K62-J62)/K62,0),) -> 0 | M62: =IF(G62<>"",I62*J62,) -> 0
C63: =IFERROR(VLOOKUP(B63,ชื่อสินค้า!A:C,2,FALSE),) -> 0 | D63: =IFERROR(VLOOKUP(B63,ชื่อสินค้า!A:D,4,FALSE),"") | G63: =IF(LEN(B63)>0,C63*E63+F63,"") | H63: =IF(B63<>"",COUNTIF($B$2:B63, B63) & "-" & B63,) -> 0 | I63: =IF(G63<>"",E63-SUMIFS(ขายสินค้า!E:E,ขายสินค้า!G:G,H63),) -> 0 | J63: =IF(G63<>"",G63/E63,) -> 0 | K63: =IF(B63<>"", IFERROR(SUMIF(ขายสินค้า!G:G,H63,ขายสินค้า!F:F)/(E63-I63),0),) -> 0 | L63: =IF(B63<>"",IFERROR((K63-J63)/K63,0),) -> 0 | M63: =IF(G63<>"",I63*J63,) -> 0
C64: =IFERROR(VLOOKUP(B64,ชื่อสินค้า!A:C,2,FALSE),) -> 0 | D64: =IFERROR(VLOOKUP(B64,ชื่อสินค้า!A:D,4,FALSE),"") | G64: =IF(LEN(B64)>0,C64*E64+F64,"") | H64: =IF(B64<>"",COUNTIF($B$2:B64, B64) & "-" & B64,) -> 0 | I64: =IF(G64<>"",E64-SUMIFS(ขายสินค้า!E:E,ขายสินค้า!G:G,H64),) -> 0 | J64: =IF(G64<>"",G64/E64,) -> 0 | K64: =IF(B64<>"", IFERROR(SUMIF(ขายสินค้า!G:G,H64,ขายสินค้า!F:F)/(E64-I64),0),) -> 0 | L64: =IF(B64<>"",IFERROR((K64-J64)/K64,0),) -> 0 | M64: =IF(G64<>"",I64*J64,) -> 0
C65: =IFERROR(VLOOKUP(B65,ชื่อสินค้า!A:C,2,FALSE),) -> 0 | D65: =IFERROR(VLOOKUP(B65,ชื่อสินค้า!A:D,4,FALSE),"") | G65: =IF(LEN(B65)>0,C65*E65+F65,"") | H65: =IF(B65<>"",COUNTIF($B$2:B65, B65) & "-" & B65,) -> 0 | I65: =IF(G65<>"",E65-SUMIFS(ขายสินค้า!E:E,ขายสินค้า!G:G,H65),) -> 0 | J65: =IF(G65<>"",G65/E65,) -> 0 | K65: =IF(B65<>"", IFERROR(SUMIF(ขายสินค้า!G:G,H65,ขายสินค้า!F:F)/(E65-I65),0),) -> 0 | L65: =IF(B65<>"",IFERROR((K65-J65)/K65,0),) -> 0 | M65: =IF(G65<>"",I65*J65,) -> 0
C66: =IFERROR(VLOOKUP(B66,ชื่อสินค้า!A:C,2,FALSE),) -> 0 | D66: =IFERROR(VLOOKUP(B66,ชื่อสินค้า!A:D,4,FALSE),"") | G66: =IF(LEN(B66)>0,C66*E66+F66,"") | H66: =IF(B66<>"",COUNTIF($B$2:B66, B66) & "-" & B66,) -> 0 | I66: =IF(G66<>"",E66-SUMIFS(ขายสินค้า!E:E,ขายสินค้า!G:G,H66),) -> 0 | J66: =IF(G66<>"",G66/E66,) -> 0 | K66: =IF(B66<>"", IFERROR(SUMIF(ขายสินค้า!G:G,H66,ขายสินค้า!F:F)/(E66-I66),0),) -> 0 | L66: =IF(B66<>"",IFERROR((K66-J66)/K66,0),) -> 0 | M66: =IF(G66<>"",I66*J66,) -> 0
... C976: =IFERROR(VLOOKUP(B976,ชื่อสินค้า!A:C,2,FALSE),) -> 0 | D976: =IFERROR(VLOOKUP(B976,ชื่อสินค้า!A:D,4,FALSE),"") | G976: =IF(LEN(B976)>0,C976*E976+F976,"") | H976: =IF(B976<>"",COUNTIF($B$2:B976, B976) & "-" & B976,) -> 0 | I976: =IF(G976<>"",E976-SUMIFS(ขายสินค้า!E:E,ขายสินค้า!G:G,H976),) -> 0 | J976: =IF(G976<>"",G976/E976,) -> 0 | K976: =IF(B976<>"", IFERROR(SUMIF(ขายสินค้า!G:G,H976,ขายสินค้า!F:F)/(E976-I976),0),) -> 0 | L976: =IF(B976<>"",IFERROR((K976-J976)/K976,0),) -> 0 | M976: =IF(G976<>"",I976*J976,) -> 0

Sheet ขายสินค้า
A1: วันที่ | B1: ชื่อสินค้า | C1: ราคา | D1: ประเภท | E1: จำนวนที่ขาย | F1: มูลค่ารวม | G1: Lot ที่ขายสินค้า | H1: สินค้าที่เหลือใน Lot | I1: ต้นทุนต่อชิ้น | J1: กำไรขั้นต้นรวม | K1: กำไรขั้นต้นต่อชิ้น | L1: % กำไรขั้นต้น | M1: ต้นทุนรวม
A2: 45657 | B2: Yamaha P-45 Digital Piano | C2: 18500 | D2: ตัว | E2: 1 | F2: 18500 | G2: 1-Yamaha P-45 Digital Piano | H2: 11 | I2: 15416.67 | J2: 3083.33 | K2: 3083.33 | L2: 0.1667 | M2: 15416.67 | N2: =IFERROR(__xludf.DUMMYFUNCTION("IF(G2<>"""",G2, IFERROR(TRANSPOSE(FILTER('ซื้อสินค้า'!H:H,'ซื้อสินค้า'!B:B=B2,'ซื้อสินค้า'!I:I>0)),))"),"1-Herschel Supply กระเป๋าสะพายหลัง รุ่น LITTLE") -> 1-Herschel Supply กระเป๋าสะพายหลัง รุ่น LITTLE
A3: 45658 | B3: Fender Player Stratocaster Electric Guitar | C3: 24900 | D3: ตัว | E3: 2 | F3: 49800 | G3: 2-Fender Player Stratocaster Electric Guitar | H3: 5 | I3: 21342.86 | J3: 8114.28 | K3: 4057.14 | L3: 0.1628 | M3: 42685.72 | N3: =IFERROR(__xludf.DUMMYFUNCTION("IF(G3<>"""",G3, IFERROR(TRANSPOSE(FILTER('ซื้อสินค้า'!H:H,'ซื้อสินค้า'!B:B=B3,'ซื้อสินค้า'!I:I>0)),))"),"1-Bellroy Australia Lite Sling 7L Light Walking") -> 1-Bellroy Australia Lite Sling 7L Light Walking
A4: 45659 | B4: Pearl Export Drum Set EXX725SP | C4: 38000 | D4: ชุด | E4: 1 | F4: 38000 | G4: 3-Pearl Export Drum Set EXX725SP | H4: 3 | I4: 28500 | J4: 9500 | K4: 9500 | L4: 0.25 | M4: 28500 | N4: =IFERROR(__xludf.DUMMYFUNCTION("IF(G4<>"""",G4, IFERROR(TRANSPOSE(FILTER('ซื้อสินค้า'!H:H,'ซื้อสินค้า'!B:B=B4,'ซื้อสินค้า'!I:I>0)),))"),"1-Herschel Supply กระเป๋าสะพายหลัง รุ่น LITTLE") -> 1-Herschel Supply กระเป๋าสะพายหลัง รุ่น LITTLE
A5: 45660 | B5: Roland GO:KEYS 61 Digital Keyboard | C5: 14900 | D5: ตัว | E5: 1 | F5: 14900 | G5: 4-Roland GO:KEYS 61 Digital Keyboard | H5: 8 | I5: 13244.44 | J5: 1655.56 | K5: 1655.56 | L5: 0.1111 | M5: 13244.44 | N5: =IFERROR(__xludf.DUMMYFUNCTION("IF(G5<>"""",G5, IFERROR(TRANSPOSE(FILTER('ซื้อสินค้า'!H:H,'ซื้อสินค้า'!B:B=B5,'ซื้อสินค้า'!I:I>0)),))"),"2-Herschel Supply กระเป๋าสะพายหลัง รุ่น LITTLE") -> 2-Herschel Supply กระเป๋าสะพายหลัง รุ่น LITTLE
A6: 45661 | B6: Suzuki M-37C Melodica | C6: 3200 | D6: ตัว | E6: 3 | F6: 9600 | G6: 5-Suzuki M-37C Melodica | H6: 22 | I6: 2816 | J6: 384 | K6: 128 | L6: 0.12 | M6: 8448 | N6: =IFERROR(__xludf.DUMMYFUNCTION("IF(G6<>"""",G6, IFERROR(TRANSPOSE(FILTER('ซื้อสินค้า'!H:H,'ซื้อสินค้า'!B:B=B6,'ซื้อสินค้า'!I:I>0)),))"),"1-Bellroy Australia Lite Sling 7L Light Walking") -> 1-Bellroy Australia Lite Sling 7L Light Walking
A7: 45662 | B7: Yamaha YFL-222 Flute | C7: 26000 | D7: ตัว | E7: 1 | F7: 26000 | G7: 6-Yamaha YFL-222 Flute | H7: 4 | I7: 20800 | J7: 5200 | K7: 5200 | L7: 0.2 | M7: 20800 | N7: =IFERROR(__xludf.DUMMYFUNCTION("IF(G7<>"""",G7, IFERROR(TRANSPOSE(FILTER('ซื้อสินค้า'!H:H,'ซื้อสินค้า'!B:B=B7,'ซื้อสินค้า'!I:I>0)),))"),"2-Herschel Supply กระเป๋าสะพายหลัง รุ่น LITTLE") -> 2-Herschel Supply กระเป๋าสะพายหลัง รุ่น LITTLE
A8: 45663 | B8: Ibanez GSR200 Bass Guitar | C8: 12500 | D8: ตัว | E8: 2 | F8: 25000 | G8: 7-Ibanez GSR200 Bass Guitar | H8: 6 | I8: 21875 | J8: 3125 | K8: 1562.5 | L8: 0.125 | M8: 21875 | N8: =IFERROR(__xludf.DUMMYFUNCTION("IF(G8<>"""",G8, IFERROR(TRANSPOSE(FILTER('ซื้อสินค้า'!H:H,'ซื้อสินค้า'!B:B=B8,'ซื้อสินค้า'!I:I>0)),))"),"1-Ergotrend เก้าอี้เพื่อสุขภาพ เออร์โกเทรน รุ่น Malmo") -> 1-Ergotrend เก้าอี้เพื่อสุขภาพ เออร์โกเทรน รุ่น Malmo
A9: 45664 | B9: Hohner Special 20 Harmonica | C9: 1800 | D9: ตัว | E9: 5 | F9: 9000 | G9: 8-Hohner Special 20 Harmonica | H9: 13 | I9: 8500 | J9: 500 | K9: 100 | L9: 0.0556 | M9: 8500 | N9: =IFERROR(__xludf.DUMMYFUNCTION("IF(G9<>"""",G9, IFERROR(TRANSPOSE(FILTER('ซื้อสินค้า'!H:H,'ซื้อสินค้า'!B:B=B9,'ซื้อสินค้า'!I:I>0)),))"),"3-Bellroy Australia Lite Sling 7L Light Walking") -> 3-Bellroy Australia Lite Sling 7L Light Walking
A10: 45665 | B10: Buffet Crampon R13 Clarinet | C10: 125000 | D10: ตัว | E10: 1 | F10: 125000 | G10: 9-Buffet Crampon R13 Clarinet | H10: 13 | I10: 110000 | J10: 15000 | K10: 15000 | L10: 0.12 | M10: 110000 | N10: =IFERROR(__xludf.DUMMYFUNCTION("IF(G10<>"""",G10, IFERROR(TRANSPOSE(FILTER('ซื้อสินค้า'!H:H,'ซื้อสินค้า'!B:B=B10,'ซื้อสินค้า'!I:I>0)),))"),"3-Bellroy Australia Lite Sling 7L Light Walking") -> 3-Bellroy Australia Lite Sling 7L Light Walking
A11: 45666 | B11: Bach Stradivarius 180S37 Trumpet | C11: 99500 | D11: ตัว | E11: 1 | F11: 99500 | G11: 10-Bach Stradivarius 180S37 Trumpet | H11: 10 | I11: 90000 | J11: 9500 | K11: 9500 | L11: 0.0955 | M11: 90000 | N11: =IFERROR(__xludf.DUMMYFUNCTION("IF(G11<>"""",G11, IFERROR(TRANSPOSE(FILTER('ซื้อสินค้า'!H:H,'ซื้อสินค้า'!B:B=B11,'ซื้อสินค้า'!I:I>0)),))"),"")
A12: 45667 | B12: Roland RP102 Digital Piano | C12: 35500 | D12: ตัว | E12: 1 | F12: 35500 | G12: 11-Roland RP102 Digital Piano | H12: 14 | I12: 31500 | J12: 4000 | K12: 4000 | L12: 0.1127 | M12: 31500 | N12: =IFERROR(__xludf.DUMMYFUNCTION("IF(G12<>"""",G12, IFERROR(TRANSPOSE(FILTER('ซื้อสินค้า'!H:H,'ซื้อสินค้า'!B:B=B12,'ซื้อสินค้า'!I:I>0)),))"),"")
A13: 45668 | B13: Stentor Student II Violin | C13: 9800 | D13: ตัว | E13: 2 | F13: 19600 | G13: 12-Stentor Student II Violin | H13: 3 | I13: 8500 | J13: 2600 | K13: 1300 | L13: 0.1327 | M13: 17000 | N13: =IFERROR(__xludf.DUMMYFUNCTION("IF(G13<>"""",G13, IFERROR(TRANSPOSE(FILTER('ซื้อสินค้า'!H:H,'ซื้อสินค้า'!B:B=B13,'ซื้อสินค้า'!I:I>0)),))"),"")
A14: 45669 | B14: Fender Jazz Bass Pro | C14: 64500 | D14: ตัว | E14: 1 | F14: 64500 | G14: 13-Fender Jazz Bass Pro | H14: 6 | I14: 60000 | J14: 4500 | K14: 4500 | L14: 0.0698 | M14: 60000 | N14: =IFERROR(__xludf.DUMMYFUNCTION("IF(G14<>"""",G14, IFERROR(TRANSPOSE(FILTER('ซื้อสินค้า'!H:H,'ซื้อสินค้า'!B:B=B14,'ซื้อสินค้า'!I:I>0)),))"),"")
A15: 45670 | B15: Yamaha Stage Custom Drum Set | C15: 32000 | D15: ชุด | E15: 1 | F15: 32000 | G15: 14-Yamaha Stage Custom Drum Set | H15: 12 | I15: 28000 | J15: 4000 | K15: 4000 | L15: 0.125 | M15: 28000 | N15: =IFERROR(__xludf.DUMMYFUNCTION("IF(G15<>"""",G15, IFERROR(TRANSPOSE(FILTER('ซื้อสินค้า'!H:H,'ซื้อสินค้า'!B:B=B15,'ซื้อสินค้า'!I:I>0)),))"),"")
A16: 45671 | B16: Aulos 205A Robin Recorder | C16: 2800 | D16: ตัว | E16: 2 | F16: 5600 | G16: 15-Aulos 205A Robin Recorder | H16: 14 | I16: 2200 | J16: 1200 | K16: 600 | L16: 0.2143 | M16: 4400 | N16: =IFERROR(__xludf.DUMMYFUNCTION("IF(G16<>"""",G16, IFERROR(TRANSPOSE(FILTER('ซื้อสินค้า'!H:H,'ซื้อสินค้า'!B:B=B16,'ซื้อสินค้า'!I:I>0)),))"),"")
A17: 45672 | B17: Ibanez RG550 Electric Guitar | C17: 41500 | D17: ตัว | E17: 1 | F17: 41500 | G17: 16-Ibanez RG550 Electric Guitar | H17: 7 | I17: 38000 | J17: 3500 | K17: 3500 | L17: 0.0843 | M17: 38000 | N17: =IFERROR(__xludf.DUMMYFUNCTION("IF(G17<>"""",G17, IFERROR(TRANSPOSE(FILTER('ซื้อสินค้า'!H:H,'ซื้อสินค้า'!B:B=B17,'ซื้อสินค้า'!I:I>0)),))"),"")
A18: 45673 | B18: GE200 Viola | C18: 13500 | D18: ตัว | E18: 1 | F18: 13500 | G18: 17-GE200 Viola | H18: 5 | I18: 11500 | J18: 2000 | K18: 2000 | L18: 0.1481 | M18: 11500 | N18: =IFERROR(__xludf.DUMMYFUNCTION("IF(G18<>"""",G18, IFERROR(TRANSPOSE(FILTER('ซื้อสินค้า'!H:H,'ซื้อสินค้า'!B:B=B18,'ซื้อสินค้า'!I:I>0)),))"),"")
A19: 45674 | B19: Mahalo Rainbow Soprano Ukulele | C19: 3000 | D19: ตัว | E19: 3 | F19: 9000 | G19: 18-Mahalo Rainbow Soprano Ukulele | H19: 17 | I19: 2500 | J19: 1500 | K19: 500 | L19: 0.1667 | M19: 7500 | N19: =IFERROR(__xludf.DUMMYFUNCTION("IF(G19<>"""",G19, IFERROR(TRANSPOSE(FILTER('ซื้อสินค้า'!H:H,'ซื้อสินค้า'!B:B=B19,'ซื้อสินค้า'!I:I>0)),))"),"")
A20: 45675 | B20: Yamaha Pianica P-37D | C20: 4000 | D20: ตัว | E20: 1 | F20: 4000 | G20: 19-Yamaha Pianica P-37D | H20: 11 | I20: 3200 | J20: 800 | K20: 800 | L20: 0.2 | M20: 3200 | N20: =IFERROR(__xludf.DUMMYFUNCTION("IF(G20<>"""",G20, IFERROR(TRANSPOSE(FILTER('ซื้อสินค้า'!H:H,'ซื้อสินค้า'!B:B=B20,'ซื้อสินค้า'!I:I>0)),))"),"")
A21: 45676 | B21: Thompson DB-200 Double Bass | C21: 46000 | D21: ตัว | E21: 1 | F21: 46000 | G21: 20-Thompson DB-200 Double Bass | H21: 8 | I21: 42000 | J21: 4000 | K21: 4000 | L21: 0.087 | M21: 42000 | N21: =IFERROR(__xludf.DUMMYFUNCTION("IF(G21<>"""",G21, IFERROR(TRANSPOSE(FILTER('ซื้อสินค้า'!H:H,'ซื้อสินค้า'!B:B=B21,'ซื้อสินค้า'!I:I>0)),))"),"")
A22: 45677 | B22: Meinl HCAJ1NT Cajon | C22: 8200 | D22: ตัว | E22: 2 | F22: 16400 | G22: 21-Meinl HCAJ1NT Cajon | H22: 2 | I22: 7000 | J22: 2400 | K22: 1200 | L22: 0.1463 | M22: 14000 | N22: =IFERROR(__xludf.DUMMYFUNCTION("IF(G22<>"""",G22, IFERROR(TRANSPOSE(FILTER('ซื้อสินค้า'!H:H,'ซื้อสินค้า'!B:B=B22,'ซื้อสินค้า'!I:I>0)),))"),"")
A23: 45678 | B23: Yamaha YAS-280 Alto Saxophone | C23: 69500 | D23: ตัว | E23: 1 | F23: 69500 | G23: 22-Yamaha YAS-280 Alto Saxophone | H23: 6 | I23: 65000 | J23: 4500 | K23: 4500 | L23: 0.0647 | M23: 65000 | N23: =IFERROR(__xludf.DUMMYFUNCTION("IF(G23<>"""",G23, IFERROR(TRANSPOSE(FILTER('ซื้อสินค้า'!H:H,'ซื้อสินค้า'!B:B=B23,'ซื้อสินค้า'!I:I>0)),))"),"")
A24: 45679 | B24: Conn-Selmer Bach TB200B Trombone | C24: 74500 | D24: ตัว | E24: 1 | F24: 74500 | G24: 23-Conn-Selmer Bach TB200B Trombone | H24: 9 | I24: 70000 | J24: 4500 | K24: 4500 | L24: 0.0604 | M24: 70000 | N24: =IFERROR(__xludf.DUMMYFUNCTION("IF(G24<>"""",G24, IFERROR(TRANSPOSE(FILTER('ซื้อสินค้า'!H:H,'ซื้อสินค้า'!B:B=B24,'ซื้อสินค้า'!I:I>0)),))"),"")
A25: 45680 | B25: Casio PX-770 Digital Piano | C25: 31500 | D25: ตัว | E25: 1 | F25: 31500 | G25: 24-Casio PX-770 Digital Piano | H25: 5 | I25: 28500 | J25: 3000 | K25: 3000 | L25: 0.0952 | M25: 28500 | N25: =IFERROR(__xludf.DUMMYFUNCTION("IF(G25<>"""",G25, IFERROR(TRANSPOSE(FILTER('ซื้อสินค้า'!H:H,'ซื้อสินค้า'!B:B=B25,'ซื้อสินค้า'!I:I>0)),))"),"")
A26: 45681 | B26: Eastman VL80 Violin | C26: 13800 | D26: ตัว | E26: 2 | F26: 27600 | G26: 25-Eastman VL80 Violin | H26: 6 | I26: 12000 | J26: 3600 | K26: 1800 | L26: 0.1304 | M26: 24000 | N26: =IFERROR(__xludf.DUMMYFUNCTION("IF(G26<>"""",G26, IFERROR(TRANSPOSE(FILTER('ซื้อสินค้า'!H:H,'ซื้อสินค้า'!B:B=B26,'ซื้อสินค้า'!I:I>0)),))"),"")
A27: 45682 | B27: Warwick Rockbass Streamer | C27: 29500 | D27: ตัว | E27: 1 | F27: 29500 | G27: 26-Warwick Rockbass Streamer | H27: 4 | I27: 27000 | J27: 2500 | K27: 2500 | L27: 0.0847 | M27: 27000 | N27: =IFERROR(__xludf.DUMMYFUNCTION("IF(G27<>"""",G27, IFERROR(TRANSPOSE(FILTER('ซื้อสินค้า'!H:H,'ซื้อสินค้า'!B:B=B27,'ซื้อสินค้า'!I:I>0)),))"),"")
A28: 45683 | B28: Tama Imperialstar Drum Set | C28: 38800 | D28: ชุด | E28: 1 | F28: 38800 | G28: 27-Tama Imperialstar Drum Set | H28: 8 | I28: 35000 | J28: 3800 | K28: 3800 | L28: 0.0979 | M28: 35000 | N28: =IFERROR(__xludf.DUMMYFUNCTION("IF(G28<>"""",G28, IFERROR(TRANSPOSE(FILTER('ซื้อสินค้า'!H:H,'ซื้อสินค้า'!B:B=B28,'ซื้อสินค้า'!I:I>0)),))"),"")
A29: 45684 | B29: Yamaha YRS-23 Recorder | C29: 1600 | D29: ตัว | E29: 4 | F29: 6400 | G29: 28-Yamaha YRS-23 Recorder | H29: 8 | I29: 1200 | J29: 1600 | K29: 400 | L29: 0.25 | M29: 4800 | N29: =IFERROR(__xludf.DUMMYFUNCTION("IF(G29<>"""",G29, IFERROR(TRANSPOSE(FILTER('ซื้อสินค้า'!H:H,'ซื้อสินค้า'!B:B=B29,'ซื้อสินค้า'!I:I>0)),))"),"")
A30: 45685 | B30: PRS SE Custom 24 Electric Guitar | C30: 31000 | D30: ตัว | E30: 1 | F30: 31000 | G30: 29-PRS SE Custom 24 Electric Guitar | H30: 6 | I30: 28000 | J30: 3000 | K30: 3000 | L30: 0.0968 | M30: 28000 | N30: =IFERROR(__xludf.DUMMYFUNCTION("IF(G30<>"""",G30, IFERROR(TRANSPOSE(FILTER('ซื้อสินค้า'!H:H,'ซื้อสินค้า'!B:B=B30,'ซื้อสินค้า'!I:I>0)),))"),"")
A31: 45686 | B31: Karl Hofner Viola H5 | C31: 17500 | D31: ตัว | E31: 1 | F31: 17500 | G31: 30-Karl Hofner Viola H5 | H31: 10 | I31: 15000 | J31: 2500 | K31: 2500 | L31: 0.1429 | M31: 15000 | N31: =IFERROR(__xludf.DUMMYFUNCTION("IF(G31<>"""",G31, IFERROR(TRANSPOSE(FILTER('ซื้อสินค้า'!H:H,'ซื้อสินค้า'!B:B=B31,'ซื้อสินค้า'!I:I>0)),))"),"")
A32: 45687 | B32: Lanikai LU-21 Ukulele | C32: 5000 | D32: ตัว | E32: 2 | F32: 10000 | G32: 31-Lanikai LU-21 Ukulele | H32: 11 | I32: 4200 | J32: 1600 | K32: 800 | L32: 0.16 | M32: 8400 | N32: =IFERROR(__xludf.DUMMYFUNCTION("IF(G32<>"""",G32, IFERROR(TRANSPOSE(FILTER('ซื้อสินค้า'!H:H,'ซื้อสินค้า'!B:B=B32,'ซื้อสินค้า'!I:I>0)),))"),"")
A33: 45688 | B33: Hohner Student 32 Melodica | C33: 4600 | D33: ตัว | E33: 1 | F33: 4600 | G33: 32-Hohner Student 32 Melodica | H33: 5 | I33: 3800 | J33: 800 | K33: 800 | L33: 0.1739 | M33: 3800 | N33: =IFERROR(__xludf.DUMMYFUNCTION("IF(G33<>"""",G33, IFERROR(TRANSPOSE(FILTER('ซื้อสินค้า'!H:H,'ซื้อสินค้า'!B:B=B33,'ซื้อสินค้า'!I:I>0)),))"),"")
A34: 45689 | B34: Cremona SB-2 Double Bass | C34: 44500 | D34: ตัว | E34: 1 | F34: 44500 | G34: 33-Cremona SB-2 Double Bass | H34: 9 | I34: 40000 | J34: 4500 | K34: 4500 | L34: 0.1011 | M34: 40000 | N34: =IFERROR(__xludf.DUMMYFUNCTION("IF(G34<>"""",G34, IFERROR(TRANSPOSE(FILTER('ซื้อสินค้า'!H:H,'ซื้อสินค้า'!B:B=B34,'ซื้อสินค้า'!I:I>0)),))"),"")
A35: 45690 | B35: Latin Percussion Aspire Conga | C35: 9800 | D35: ตัว | E35: 2 | F35: 19600 | G35: 34-Latin Percussion Aspire Conga | H35: 13 | I35: 8500 | J35: 2600 | K35: 1300 | L35: 0.1327 | M35: 17000 | N35: =IFERROR(__xludf.DUMMYFUNCTION("IF(G35<>"""",G35, IFERROR(TRANSPOSE(FILTER('ซื้อสินค้า'!H:H,'ซื้อสินค้า'!B:B=B35,'ซื้อสินค้า'!I:I>0)),))"),"")
A36: 45691 | B36: Selmer Paris Reference 54 Alto Saxophone | C36: 190000 | D36: ตัว | E36: 1 | F36: 190000 | G36: 35-Selmer Paris Reference 54 Alto Saxophone | H36: 7 | I36: 185000 | J36: 5000 | K36: 5000 | L36: 0.0263 | M36: 185000 | N36: =IFERROR(__xludf.DUMMYFUNCTION("IF(G36<>"""",G36, IFERROR(TRANSPOSE(FILTER('ซื้อสินค้า'!H:H,'ซื้อสินค้า'!B:B=B36,'ซื้อสินค้า'!I:I>0)),))"),"")
A37: 45692 | B37: Yamaha YTR-2330 Trumpet | C37: 38500 | D37: ตัว | E37: 1 | F37: 38500 | G37: 36-Yamaha YTR-2330 Trumpet | H37: 8 | I37: 35000 | J37: 3500 | K37: 3500 | L37: 0.0909 | M37: 35000 | N37: =IFERROR(__xludf.DUMMYFUNCTION("IF(G37<>"""",G37, IFERROR(TRANSPOSE(FILTER('ซื้อสินค้า'!H:H,'ซื้อสินค้า'!B:B=B37,'ซื้อสินค้า'!I:I>0)),))"),"")
A38: 45693 | B38: Kawai KDP110 Digital Piano | C38: 46500 | D38: ตัว | E38: 1 | F38: 46500 | G38: 37-Kawai KDP110 Digital Piano | H38: 13 | I38: 42000 | J38: 4500 | K38: 4500 | L38: 0.0968 | M38: 42000 | N38: =IFERROR(__xludf.DUMMYFUNCTION("IF(G38<>"""",G38, IFERROR(TRANSPOSE(FILTER('ซื้อสินค้า'!H:H,'ซื้อสินค้า'!B:B=B38,'ซื้อสินค้า'!I:I>0)),))"),"")
A39: 45694 | B39: Gliga Gems 2 Violin | C39: 20500 | D39: ตัว | E39: 1 | F39: 20500 | G39: 38-Gliga Gems 2 Violin | H39: 4 | I39: 18000 | J39: 2500 | K39: 2500 | L39: 0.122 | M39: 18000 | N39: =IFERROR(__xludf.DUMMYFUNCTION("IF(G39<>"""",G39, IFERROR(TRANSPOSE(FILTER('ซื้อสินค้า'!H:H,'ซื้อสินค้า'!B:B=B39,'ซื้อสินค้า'!I:I>0)),))"),"")
A40: 45695 | B40: Fender Precision Bass | C40: 59500 | D40: ตัว | E40: 2 | F40: 119000 | G40: 39-Fender Precision Bass | H40: 4 | I40: 55000 | J40: 9000 | K40: 4500 | L40: 0.1525 | M40: 110000 | N40: =IFERROR(__xludf.DUMMYFUNCTION("IF(G40<>"""",G40, IFERROR(TRANSPOSE(FILTER('ซื้อสินค้า'!H:H,'ซื้อสินค้า'!B:B=B40,'ซื้อสินค้า'!I:I>0)),))"),"")
...

Sheet ชื่อสินค้า
A1: ชื่อสินค้า | B1: ราคาซื้อ | C1: ราคาขาย | D1: ประเภท | E1: หมวด/ชนิด | F1: แบรนด์
A2: Digital Piano DP-135 RW | B2: 40500 | C2: 43500 | D2: Piano | E2: Digital Piano | F2: Custom
A3: Strings CV240 | B3: 26500 | C3: 27500 | D3: Violin | E3: Violin | F3: Cecilia
A4: Fender American Ultra II | B4: 80,00 | C4: 85500 | D4: Brass | E4: Jazz Bass | F4: Fender
A5: Hampback ACE-530 | B5: 25000 | C5: 28500 | D5: Drum | E5: Electronic Drum | F5: Hampback
A6: Model MTDB-1 | B6: 37000 | C6: 38500 | D6: DB-Bass | E6: Double Bass | F6: Custom
A7: EL100 | B7: 10000 | C7: 12500 | D7: Viola | E7: Viola | F7: Elman
A8: Digital Piano DP-135 RW | B8: 40500 | C8: 43500 | D8: Piano | E8: Digital Piano | F8: Custom
A9: Strings CV240 | B9: 26500 | C9: 27500 | D9: Violin | E9: Violin | F9: Cecilia
A10: Fender American Ultra II | B10: 80000 | C10: 85500 | D10: Brass | E10: Jazz Bass | F10: Fender
A11: Hampback ACE-530 | B11: 25000 | C11: 28500 | D11: Drum | E11: Electronic Drum | F11: Hampback
A12: Yamaha YRT-304B | B12: 3500 | C12: 4200 | D12: Recorder | E12: Recorder | F12: Yamaha
A13: Gibson Les Paul Studio | B13: 45000 | C13: 48500 | D13: Guitar | E13: Electric Guitar | F13: Gibson
A14: EL100 | B14: 10000 | C14: 12500 | D14: Viola | E14: Viola | F14: Elman
A15: Kala KA-15S | B15: 3800 | C15: 4500 | D15: Ukulele | E15: Standard Ukulele | F15: Kala
A16: Suzuki Melodion M-32C | B16: 2500 | C16: 3200 | D16: Melodica | E16: Melodica | F16: Suzuki
... A58: Yamaha YCL-255 | B58: 42000 | C58: 45500 | D58: Woodwind | E58: Clarinet | F58: Yamaha

Sheet รายงานสินค้าคงเหลือ
A1: ชื่อสินค้า | B1: หน่วยนับ | C1: จำนวนคงเหลือ | D1: มูลค่าสินค้าคงเหลือ | E1: มูลค่าสินค้าคงเหลือเฉลี่ยต่อชิ้น
A2: Digital Piano DP-135 RW | B2: ตัว | C2: 12 | D2: 43500 | E2: 3625
A3: Strings CV240 | B3: ตัว | C3: 7 | D3: 27500 | E3: 3928.57
A4: Fender American Ultra II | B4: ตัว | C4: 4 | D4: 85500 | E4: 21375
A5: Hampback ACE-530 | B5: ชุด | C5: 9 | D5: 28500 | E5: 3166.67
A6: Yamaha YRT-304B | B6: ตัว | C6: 25 | D6: 4200 | E6: 168
A7: Gibson Les Paul Studio | B7: ตัว | C7: 5 | D7: 48500 | E7: 9700
A8: EL100 | B8: ตัว | C8: 8 | D8: 12500 | E8: 1562.5
A9: Kala KA-15S | B9: ตัว | C9: 18 | D9: 4500 | E9: 250
A10: Suzuki Melodion M-32C | B10: ตัว | C10: 6 | D10: 3200 | E10: 533.33
A11: Model MTDB-1 | B11: ตัว | C11: 10 | D11: 38500 | E11: 3850
A12: Pearl PCTK-1810 | B12: ตัว | C12: 3 | D12: 22500 | E12: 7500
A13: Buffet Crampon R13 | B13: ตัว | C13: 14 | D13: 125000 | E13: 8928.57
... A51: Pearl Roadshow | B51: ชุด | C51: 9 | D51: 25500 | E51: 2833.33
B52: =IFERROR(VLOOKUP(A52,ชื่อสินค้า!A:D,4,FALSE),) -> 0 | C52: =IF(A52<>"",SUMIF(ซื้อสินค้า!B:B,A52,ซื้อสินค้า!E:E)-SUMIF(ขายสินค้า!B:B,A52,ขายสินค้า!E:E),) -> 0 | D52: =IF(A52<>"",SUMIF(ซื้อสินค้า!B:B,A52,ซื้อสินค้า!M:M),) -> 0 | E52: =IFERROR(IF(A52<>"",D52/C52,),0) -> 0
B53: =IFERROR(VLOOKUP(A53,ชื่อสินค้า!A:D,4,FALSE),) -> 0 | C53: =IF(A53<>"",SUMIF(ซื้อสินค้า!B:B,A53,ซื้อสินค้า!E:E)-SUMIF(ขายสินค้า!B:B,A53,ขายสินค้า!E:E),) -> 0 | D53: =IF(A53<>"",SUMIF(ซื้อสินค้า!B:B,A53,ซื้อสินค้า!M:M),) -> 0 | E53: =IFERROR(IF(A53<>"",D53/C53,),0) -> 0
C54: =IF(A54<>"",SUMIF(ซื้อสินค้า!B:B,A54,ซื้อสินค้า!E:E)-SUMIF(ขายสินค้า!B:B,A54,ขายสินค้า!E:E),) -> 0 | D54: =IF(A54<>"",SUMIF(ซื้อสินค้า!B:B,A54,ซื้อสินค้า!M:M),) -> 0 | E54: =IFERROR(IF(A54<>"",D54/C54,),0) -> 0
B55: =IFERROR(VLOOKUP(A55,ชื่อสินค้า!A:D,4,FALSE),) -> 0 | C55: =IF(A55<>"",SUMIF(ซื้อสินค้า!B:B,A55,ซื้อสินค้า!E:E)-SUMIF(ขายสินค้า!B:B,A55,ขายสินค้า!E:E),) -> 0 | D55: =IF(A55<>"",SUMIF(ซื้อสินค้า!B:B,A55,ซื้อสินค้า!M:M),) -> 0 | E55: =IFERROR(IF(A55<>"",D55/C55,),0) -> 0
B56: =IFERROR(VLOOKUP(A56,ชื่อสินค้า!A:D,4,FALSE),) -> 0 | C56: =IF(A56<>"",SUMIF(ซื้อสินค้า!B:B,A56,ซื้อสินค้า!E:E)-SUMIF(ขายสินค้า!B:B,A56,ขายสินค้า!E:E),) -> 0 | D56: =IF(A56<>"",SUMIF(ซื้อสินค้า!B:B,A56,ซื้อสินค้า!M:M),) -> 0 | E56: =IFERROR(IF(A56<>"",D56/C56,),0) -> 0
B57: =IFERROR(VLOOKUP(A57,ชื่อสินค้า!A:D,4,FALSE),) -> 0 | C57: =IF(A57<>"",SUMIF(ซื้อสินค้า!B:B,A57,ซื้อสินค้า!E:E)-SUMIF(ขายสินค้า!B:B,A57,ขายสินค้า!E:E),) -> 0 | D57: =IF(A57<>"",SUMIF(ซื้อสินค้า!B:B,A57,ซื้อสินค้า!M:M),) -> 0 | E57: =IFERROR(IF(A57<>"",D57/C57,),0) -> 0
B58: =IFERROR(VLOOKUP(A58,ชื่อสินค้า!A:D,4,FALSE),) -> 0 | C58: =IF(A58<>"",SUMIF(ซื้อสินค้า!B:B,A58,ซื้อสินค้า!E:E)-SUMIF(ขายสินค้า!B:B,A58,ขายสินค้า!E:E),) -> 0 | D58: =IF(A58<>"",SUMIF(ซื้อสินค้า!B:B,A58,ซื้อสินค้า!M:M),) -> 0 | E58: =IFERROR(IF(A58<>"",D58/C58,),0) -> 0
B59: =IFERROR(VLOOKUP(A59,ชื่อสินค้า!A:D,4,FALSE),) -> 0 | C59: =IF(A59<>"",SUMIF(ซื้อสินค้า!B:B,A59,ซื้อสินค้า!E:E)-SUMIF(ขายสินค้า!B:B,A59,ขายสินค้า!E:E),) -> 0 | D59: =IF(A59<>"",SUMIF(ซื้อสินค้า!B:B,A59,ซื้อสินค้า!M:M),) -> 0 | E59: =IFERROR(IF(A59<>"",D59/C59,),0) -> 0
B60: =IFERROR(VLOOKUP(A60,ชื่อสินค้า!A:D,4,FALSE),) -> 0 | C60: =IF(A60<>"",SUMIF(ซื้อสินค้า!B:B,A60,ซื้อสินค้า!E:E)-SUMIF(ขายสินค้า!B:B,A60,ขายสินค้า!E:E),) -> 0 | D60: =IF(A60<>"",SUMIF(ซื้อสินค้า!B:B,A60,ซื้อสินค้า!M:M),) -> 0 | E60: =IFERROR(IF(A60<>"",D60/C60,),0) -> 0
B61: =IFERROR(VLOOKUP(A61,ชื่อสินค้า!A:D,4,FALSE),) -> 0 | C61: =IF(A61<>"",SUMIF(ซื้อสินค้า!B:B,A61,ซื้อสินค้า!E:E)-SUMIF(ขายสินค้า!B:B,A61,ขายสินค้า!E:E),) -> 0 | D61: =IF(A61<>"",SUMIF(ซื้อสินค้า!B:B,A61,ซื้อสินค้า!M:M),) -> 0 | E61: =IFERROR(IF(A61<>"",D61/C61,),0) -> 0
B62: =IFERROR(VLOOKUP(A62,ชื่อสินค้า!A:D,4,FALSE),) -> 0 | C62: =IF(A62<>"",SUMIF(ซื้อสินค้า!B:B,A62,ซื้อสินค้า!E:E)-SUMIF(ขายสินค้า!B:B,A62,ขายสินค้า!E:E),) -> 0 | D62: =IF(A62<>"",SUMIF(ซื้อสินค้า!B:B,A62,ซื้อสินค้า!M:M),) -> 0 | E62: =IFERROR(IF(A62<>"",D62/C62,),0) -> 0
B63: =IFERROR(VLOOKUP(A63,ชื่อสินค้า!A:D,4,FALSE),) -> 0 | C63: =IF(A63<>"",SUMIF(ซื้อสินค้า!B:B,A63,ซื้อสินค้า!E:E)-SUMIF(ขายสินค้า!B:B,A63,ขายสินค้า!E:E),) -> 0 | D63: =IF(A63<>"",SUMIF(ซื้อสินค้า!B:B,A63,ซื้อสินค้า!M:M),) -> 0 | E63: =IFERROR(IF(A63<>"",D63/C63,),0) -> 0
B64: =IFERROR(VLOOKUP(A64,ชื่อสินค้า!A:D,4,FALSE),) -> 0 | C64: =IF(A64<>"",SUMIF(ซื้อสินค้า!B:B,A64,ซื้อสินค้า!E:E)-SUMIF(ขายสินค้า!B:B,A64,ขายสินค้า!E:E),) -> 0 | D64: =IF(A64<>"",SUMIF(ซื้อสินค้า!B:B,A64,ซื้อสินค้า!M:M),) -> 0 | E64: =IFERROR(IF(A64<>"",D64/C64,),0) -> 0
B65: =IFERROR(VLOOKUP(A65,ชื่อสินค้า!A:D,4,FALSE),) -> 0 | C65: =IF(A65<>"",SUMIF(ซื้อสินค้า!B:B,A65,ซื้อสินค้า!E:E)-SUMIF(ขายสินค้า!B:B,A65,ขายสินค้า!E:E),) -> 0 | D65: =IF(A65<>"",SUMIF(ซื้อสินค้า!B:B,A65,ซื้อสินค้า!M:M),) -> 0 | E65: =IFERROR(IF(A65<>"",D65/C65,),0) -> 0
B66: =IFERROR(VLOOKUP(A66,ชื่อสินค้า!A:D,4,FALSE),) -> 0 | C66: =IF(A66<>"",SUMIF(ซื้อสินค้า!B:B,A66,ซื้อสินค้า!E:E)-SUMIF(ขายสินค้า!B:B,A66,ขายสินค้า!E:E),) -> 0 | D66: =IF(A66<>"",SUMIF(ซื้อสินค้า!B:B,A66,ซื้อสินค้า!M:M),) -> 0 | E66: =IFERROR(IF(A66<>"",D66/C66,),0) -> 0
... B1000: =IFERROR(VLOOKUP(A1000,ชื่อสินค้า!A:D,4,FALSE),) -> 0 | C1000: =IF(A1000<>"",SUMIF(ซื้อสินค้า!B:B,A1000,ซื้อสินค้า!E:E)-SUMIF(ขายสินค้า!B:B,A1000,ขายสินค้า!E:E),) -> 0 | D1000: =IF(A1000<>"",SUMIF(ซื้อสินค้า!B:B,A1000,ซื้อสินค้า!M:M),) -> 0 | E1000: =IFERROR(IF(A1000<>"",D1000/C1000,),0) -> 0

Sheet รายงานเคลื่อนไหวสินค้า
A2: 📦 เลือกสินค้า | B2: Herschel Supply กระเป๋าสะพายหลัง รุ่น LITTLE
B5: ⬇️ มูลค่าซื้อรวม | C5: =SUMPRODUCT(D9:D1001, C9:C1001) -> 3002000 | E5: ⬇️ จำนวนซื้อรวม | F5: =SUM(C9:C1001) -> 109 | J5: ⬆️ มูลค่าขายรวม | K5: =SUM(K9) -> 1 | M5: ⬆️ จำนวนขายรวม | N5: =SUM(K9:K1001) -> 109
A7: รายการซื้อสินค้า | I7: รายงานขายสินค้า
A8: วันที่ | B8: ราคาที่ซื้อ | C8: จำนวนที่ซื้อ | D8: มูลค่ารวมซื้อ | E8: สินค้าลงเหลือใน lot | F8: อัตรากำไรขั้นต้น % | G8: เลข Lot | I8: วันที่ | J8: ราคาขาย | K8: จำนวนที่ขาย | L8: มูลค่ารวมขาย | M8: กำไรขั้นต้นต่อชิ้น | N8: ต้นทุนสินค้าต่อชิ้น | O8: อัตรากำไรขั้นต้น | P8: เลข Lot
A9: 45658 | B9: 18500 | C9: 1 | D9: 18500 | E9: 0 | F9: 0.2 | G9: 1-Yamaha P-45 | I9: 45662 | J9: 22000 | K9: 1 | L9: 22000 | M9: 3500 | N9: 18500 | O9: 0.15 | P9: 1-Yamaha P-45
A10: 45659 | B10: 24900 | C10: 2 | D10: 49800 | E10: 0 | F10: 0.25 | G10: 2-Fender Strat | I10: 45663 | J10: 31000 | K10: 2 | L10: 62000 | M10: 6100 | N10: 24900 | O10: 0.195 | P10: 2-Fender Strat
A11: 45660 | B11: 38000 | C11: 1 | D11: 38000 | E11: 0 | F11: 0.22 | G11: 3-Pearl Drum | I11: 45664 | J11: 46000 | K11: 1 | L11: 46000 | M11: 8000 | N11: 38000 | O11: 0.2174 | P11: 3-Pearl Drum
A12: 45661 | B12: 14900 | C12: 3 | D12: 44700 | E12: 1 | F12: 0.18 | G12: 4-Roland GO | I12: 45665 | J12: 17000 | K12: 3 | L12: 51000 | M12: 2100 | N12: 14900 | O12: 0.125 | P12: 4-Roland GO
A13: 45662 | B13: 3200 | C13: 5 | D13: 16000 | E13: 2 | F13: 0.15 | G13: 5-Suzuki M-37C | I13: 45666 | J13: 3700 | K13: 5 | L13: 18500 | M13: 500 | N13: 3200 | O13: 0.1351 | P13: 5-Suzuki M-37C
A14: 45663 | B14: 26000 | C14: 2 | D14: 52000 | E14: 1 | F14: 0.2 | G14: 6-Yamaha Flute | I14: 45667 | J14: 32000 | K14: 2 | L14: 64000 | M14: 6000 | N14: 26000 | O14: 0.1875 | P14: 6-Yamaha Flute
A15: 45664 | B15: 12500 | C15: 3 | D15: 37500 | E15: 2 | F15: 0.15 | G15: 7-Ibanez Bass | I15: 45668 | J15: 14500 | K15: 3 | L15: 43500 | M15: 2000 | N15: 12500 | O15: 0.16 | P15: 7-Ibanez Bass
A16: 45665 | B16: 1800 | C16: 4 | D16: 7200 | E16: 1 | F16: 0.1 | G16: 8-Hohner Harmonica | I16: 45669 | J16: 2000 | K16: 4 | L16: 8000 | M16: 200 | N16: 1800 | O16: 0.1111 | P16: 8-Hohner Harmonica
A17: 45666 | B17: 18500 | C17: 2 | D17: 37000 | E17: 0 | F17: 0.2 | G17: 9-Yamaha P-45 | I17: 45670 | J17: 22000 | K17: 2 | L17: 44000 | M17: 3500 | N17: 18500 | O17: 0.1591 | P17: 9-Yamaha P-45
A18: 45667 | B18: 24900 | C18: 1 | D18: 24900 | E18: 0 | F18: 0.25 | G18: 10-Fender Strat | I18: 45671 | J18: 31000 | K18: 1 | L18: 31000 | M18: 6100 | N18: 24900 | O18: 0.1952 | P18: 10-Fender Strat
A19: 45668 | B19: 38000 | C19: 2 | D19: 76000 | E19: 1 | F19: 0.22 | G19: 11-Pearl Drum | I19: 45672 | J19: 46000 | K19: 2 | L19: 92000 | M19: 8000 | N19: 38000 | O19: 0.2174 | P19: 11-Pearl Drum
A20: 45669 | B20: 14900 | C20: 1 | D20: 14900 | E20: 0 | F20: 0.18 | G20: 12-Roland GO | I20: 45673 | J20: 17000 | K20: 1 | L20: 17000 | M20: 2100 | N20: 14900 | O20: 0.125 | P20: 12-Roland GO
... A58: 45707 | B58: 24900 | C58: 2 | D58: 49800 | E58: 0 | F58: 0.25 | G58: 50-Fender Strat | I58: 45711 | J58: 31000 | K58: 2 | L58: 62000 | M58: 6100 | N58: 24900 | O58: 0.1952 | P58: 50-Fender Strat

Sheet รายงานสรุปยอดขายและกำไรขั้นต้น
A1: เลือกปี | B1: 2025
B18: เดือน | C18: =DATE($B$1,1,1) -> 45658 | D18: =DATE($B$1,2,1) -> 45689 | E18: =DATE($B$1,3,1) -> 45717 | F18: =DATE($B$1,4,1) -> 45748 | G18: =DATE($B$1,5,1) -> 45778 | H18: =DATE($B$1,6,1) -> 45809 | I18: =DATE($B$1,7,1) -> 45839 | J18: =DATE($B$1,8,1) -> 45870 | K18: =DATE($B$1,9,1) -> 45901 | L18: =DATE($B$1,10,1) -> 45931 | M18: =DATE($B$1,11,1) -> 45962 | N18: =DATE($B$1,12,1) -> 45992
B19: ยอดขายรวม | C19: 980500 | D19: =SUMIFS(ขายสินค้า!$F:$F,ขายสินค้า!$A:$A,">="&D$18,ขายสินค้า!$A:$A,"<="&EOMONTH(D$18,0)) -> 611900 | E19: =SUMIFS(ขายสินค้า!$F:$F,ขายสินค้า!$A:$A,">="&E$18,ขายสินค้า!$A:$A,"<="&EOMONTH(E$18,0)) -> 0 | F19: =SUMIFS(ขายสินค้า!$F:$F,ขายสินค้า!$A:$A,">="&F$18,ขายสินค้า!$A:$A,"<="&EOMONTH(F$18,0)) -> 0 | G19: =SUMIFS(ขายสินค้า!$F:$F,ขายสินค้า!$A:$A,">="&G$18,ขายสินค้า!$A:$A,"<="&EOMONTH(G$18,0)) -> 0 | H19: =SUMIFS(ขายสินค้า!$F:$F,ขายสินค้า!$A:$A,">="&H$18,ขายสินค้า!$A:$A,"<="&EOMONTH(H$18,0)) -> 0 | I19: =SUMIFS(ขายสินค้า!$F:$F,ขายสินค้า!$A:$A,">="&I$18,ขายสินค้า!$A:$A,"<="&EOMONTH(I$18,0)) -> 0 | J19: =SUMIFS(ขายสินค้า!$F:$F,ขายสินค้า!$A:$A,">="&J$18,ขายสินค้า!$A:$A,"<="&EOMONTH(J$18,0)) -> 0 | K19: =SUMIFS(ขายสินค้า!$F:$F,ขายสินค้า!$A:$A,">="&K$18,ขายสินค้า!$A:$A,"<="&EOMONTH(K$18,0)) -> 0 | ... N19: =SUMIFS(ขายสินค้า!$F:$F,ขายสินค้า!$A:$A,">="&N$18,ขายสินค้า!$A:$A,"<="&EOMONTH(N$18,0)) -> 0
B20: ต้นทุนรวม | C20: =SUMIFS(ขายสินค้า!$M:$M,ขายสินค้า!$A:$A,">="&C$18,ขายสินค้า!$A:$A,"<="&EOMONTH(C$18,0)) -> 910653.16 | D20: =SUMIFS(ขายสินค้า!$M:$M,ขายสินค้า!$A:$A,">="&D$18,ขายสินค้า!$A:$A,"<="&EOMONTH(D$18,0)) -> 564500 | E20: =SUMIFS(ขายสินค้า!$M:$M,ขายสินค้า!$A:$A,">="&E$18,ขายสินค้า!$A:$A,"<="&EOMONTH(E$18,0)) -> 0 | F20: =SUMIFS(ขายสินค้า!$M:$M,ขายสินค้า!$A:$A,">="&F$18,ขายสินค้า!$A:$A,"<="&EOMONTH(F$18,0)) -> 0 | G20: =SUMIFS(ขายสินค้า!$M:$M,ขายสินค้า!$A:$A,">="&G$18,ขายสินค้า!$A:$A,"<="&EOMONTH(G$18,0)) -> 0 | H20: =SUMIFS(ขายสินค้า!$M:$M,ขายสินค้า!$A:$A,">="&H$18,ขายสินค้า!$A:$A,"<="&EOMONTH(H$18,0)) -> 0 | I20: =SUMIFS(ขายสินค้า!$M:$M,ขายสินค้า!$A:$A,">="&I$18,ขายสินค้า!$A:$A,"<="&EOMONTH(I$18,0)) -> 0 | J20: =SUMIFS(ขายสินค้า!$M:$M,ขายสินค้า!$A:$A,">="&J$18,ขายสินค้า!$A:$A,"<="&EOMONTH(J$18,0)) -> 0 | ... N20: =SUMIFS(ขายสินค้า!$M:$M,ขายสินค้า!$A:$A,">="&N$18,ขายสินค้า!$A:$A,"<="&EOMONTH(N$18,0)) -> 0
B21: กำไรขั้นต้น | C21: =C19-C20 -> 69846.84 | D21: =D19-D20 -> 47400 | E21: =E19-E20 -> 0 | F21: =F19-F20 -> 0 | G21: =G19-G20 -> 0 | H21: =H19-H20 -> 0 | I21: =I19-I20 -> 0 | J21: =J19-J20 -> 0 | ... N21: =N19-N20 -> 0
B22: %กำไรขั้นต้น | C22: =IFERROR(C21/C19,0) -> 0.071235941 | D22: =IFERROR(D21/D19,0) -> 0.077463638 | E22: =IFERROR(E21/E19,0) -> 0 | F22: =IFERROR(F21/F19,0) -> 0 | G22: =IFERROR(G21/G19,0) -> 0 | H22: =IFERROR(H21/H19,0) -> 0 | I22: =IFERROR(I21/I19,0) -> 0 | J22: =IFERROR(J21/J19,0) -> 0 | ... N22: =IFERROR(N21/N19,0) -> 0
B23: กำไรขั้นต้นสะสม | C23: =C21 -> 69846.84 | D23: =C23+D21 -> 117246.84 | E23: =E26 -> 0 | F23: =E23+F21 -> 0 | G23: =F23+G21 -> 0 | H23: =G23+H21 -> 0 | I23: =H23+I21 -> 0 | J23: =I23+J21 -> 0 | K23: =J23+K21 -> 0 | L23: =K23+L21 -> 0 | M23: =L23+M21 -> 0 | N23: =M23+N21 -> 0
